<?xml version="1.0" ?>
<robot name="microwave">
   <material name="obj_color">
      <color rgba="1.0 0.423529411765 0.0392156862745 1.0"/>
   </material>
   <link name="top">
      <inertial>
         <origin rpy="0.0001221233215210107 0.000149726575729481 0.0002687447291068319" xyz="0.03453060399819297 0.07699720843971504 -0.05723462521229605"/>
         <mass value="0.07647572865540518"/>
         <inertia ixx="0.0002444236299574754" ixy="-5.450006901894448e-05" ixz="1.725560696732394e-06" iyy="0.0001464131365626052" iyz="-1.067326896674499e-06" izz="0.0001497578598372431"/>
      </inertial>
      <visual>
         <origin rpy="0 0 0" xyz="0 0 0"/>
         <geometry>
            <mesh filename="top_watertight_tiny.stl" scale="1 1 1"/>
         </geometry>
         <material name="obj_color"/>
      </visual>
      <collision>
         <origin rpy="0 0 0" xyz="0 0 0"/>
         <geometry>
            <mesh filename="top_watertight_tiny.obj" scale="1 1 1"/>
         </geometry>
      </collision>
   </link>
   <link name="bottom">
      <inertial>
         <origin rpy="0.009602305095953124 0.01649846082415188 0.01654763985318345" xyz="-0.01388002111063888 0.153928998699511 -0.05565604419550656"/>
         <mass value="2.340557125725653"/>
         <inertia ixx="0.01538539034209968" ixy="-0.002570831878595432" ixz="-3.479358636578293e-05" iyy="0.01074851784815466" iyz="-0.0001370781132866528" izz="0.01651449758303411"/>
      </inertial>
      <visual>
         <origin rpy="0 0 0" xyz="0 0 0"/>
         <geometry>
            <mesh filename="bottom_watertight_tiny.stl" scale="1 1 1"/>
         </geometry>
         <material name="obj_color"/>
      </visual>
      <collision>
         <origin rpy="0 0 0" xyz="0 0 0"/>
         <geometry>
            <mesh filename="bottom_watertight_tiny.obj" scale="1 1 1"/>
         </geometry>
      </collision>
   </link>
   <link name="world"/>
   <joint name="world_to_base" type="fixed">
      <origin xyz="0 0 0"/>
      <axis xyz="0 0 0"/>
      <parent link="world"/>
      <child link="bottom"/>
   </joint>
   <joint name="rotation" type="revolute">
      <origin xyz="0 0 0"/>
      <axis xyz="0 0 -1"/>
      <parent link="bottom"/>
      <child link="top"/>
      <dynamics damping="0.05" friction="0.0001"/>
      <limit effort="1000" velocity="200" lower="0" upper="3.141592653589793"/>
   </joint>
</robot>
