<?xml version="1.0" ?>
<robot name="espressomachine">
   <material name="obj_color">
      <color rgba="1.0 0.423529411765 0.0392156862745 1.0"/>
   </material>
   <link name="top">
      <inertial>
         <origin rpy="3.82122850027815e-07 8.492017527599243e-06 8.494734613340323e-06" xyz="0.1068153423158261 -0.05591814060690717 -0.02125180239214495"/>
         <mass value="0.0127211668828713"/>
         <inertia ixx="3.663457546836962e-06" ixy="3.981205735385069e-06" ixz="-2.079743509077856e-08" iyy="5.212679001159405e-06" iyz="1.553389498843983e-08" izz="8.492738442971016e-06"/>
      </inertial>
      <visual>
         <origin rpy="0 0 0" xyz="0 0 0"/>
         <geometry>
            <mesh filename="top_watertight_tiny.stl" scale="1 1 1"/>
         </geometry>
         <material name="obj_color"/>
      </visual>
      <collision>
         <origin rpy="0 0 0" xyz="0 0 0"/>
         <geometry>
            <mesh filename="top_watertight_tiny.obj" scale="1 1 1"/>
         </geometry>
      </collision>
   </link>
   <link name="bottom">
      <inertial>
         <origin rpy="0.006824255882152636 0.01152968483575309 0.01501223289888379" xyz="-0.04169068669083825 -0.03542646983331282 -0.01861851357806351"/>
         <mass value="1.892773469188377"/>
         <inertia ixx="0.009613588437882863" ixy="-0.003859634336621988" ixz="-7.812862557022443e-05" iyy="0.0121859629421628" iyz="0.0004242342099542514" izz="0.01156662223674385"/>
      </inertial>
      <visual>
         <origin rpy="0 0 0" xyz="0 0 0"/>
         <geometry>
            <mesh filename="bottom_watertight_tiny.stl" scale="1 1 1"/>
         </geometry>
         <material name="obj_color"/>
      </visual>
      <collision>
         <origin rpy="0 0 0" xyz="0 0 0"/>
         <geometry>
            <mesh filename="bottom_watertight_tiny.obj" scale="1 1 1"/>
         </geometry>
      </collision>
   </link>
   <joint name="rotation" type="revolute">
      <origin xyz="0 0 0"/>
      <axis xyz="0 0 -1"/>
      <parent link="bottom"/>
      <child link="top"/>
      <dynamics damping="0.05" friction="0.0001"/>
      <limit effort="1000" velocity="200" lower="0" upper="1.5"/>
   </joint>
</robot>
