<?xml version="0.0" ?>
<robot name="mano">



    <!-- Base link -->
    <link name="base">

    </link>
    <!-- Fixed joint to add dummy inertia link -->
    <joint name="base_to_base_inertia" type="fixed">
        <parent link="base"/>
        <child link="base_inertia"/>
        <origin rpy="0 0 0" xyz="0 0 0"/>
    </joint>
    <!-- Dummy inertia link, because KDL cannot have inertia on the base link -->
    <link name="base_inertia">
        <inertial>
            <origin rpy="0 0 0" xyz="-0.001960558279 -0.001413217745 0.050207125344"/>
            <mass value="16.793507758"/>
            <inertia ixx="0.217391101503" ixy="-0.00132873239126" ixz="-0.00228200226173" iyy="0.639432546734" iyz="-0.00138078263145" izz="0.62414077654"/>
        </inertial>
    </link>

    <!--
      Palm
    -->
    <!-- Palm -->
    <link name="palm">
        <visual>
            <origin rpy="0 0 0.0" xyz="0 0 0"/>
            <geometry>
                <mesh filename="meshes/palm_norm2.stl" scale="1 1 1"/>
            </geometry>
        </visual>
        <inertial>
            <origin rpy="0.00000 -0.00000 0.00000" xyz="0.00000 0.00000 0.00000"/>
            <mass value="0.00647"/>
            <inertia ixx="0.00000" ixy="0" ixz="0" iyy="0.00000" iyz="0" izz="0.00000"/>
        </inertial>
        <collision>
            <origin rpy="-2.88478 1.34121 -2.81888" xyz="-0.04275 -0.00254 0.00966"/>
            <geometry>
                <capsule length="0.08780" radius="0.00750"/>
            </geometry>
        </collision>
        <collision>
            <origin rpy="-0.16564 1.26174 -0.12112" xyz="-0.03968 -0.00209 -0.01249"/>
            <geometry>
                <capsule length="0.08330" radius="0.00750"/>
            </geometry>
        </collision>
        <collision>
            <origin rpy="-0.22687 1.01490 -0.12652" xyz="-0.03353 -0.00468 -0.02029"/>
            <geometry>
                <capsule length="0.07894" radius="0.00750"/>
            </geometry>
        </collision>
        <collision>
            <origin rpy="-2.61505 0.70030 -1.87000" xyz="-0.01187 -0.00708 0.01218"/>
            <geometry>
                <capsule length="0.03684" radius="0.00750"/>
            </geometry>
        </collision>
        <collision>
            <origin rpy="-0.51070 1.52915 -0.49070" xyz="-0.04585 -0.00093 -0.00167"/>
            <geometry>
                <capsule length="0.09178" radius="0.00750"/>
            </geometry>
        </collision>

    </link>
    <!-- Hip joint -->
    <joint name="WRJ0x" type="prismatic">
        <parent link="base"/>
        <child link="palm"/>
        <origin xyz="0.0 0.0 0.0"/>
        <axis xyz="1 0 0"/>
        <limit effort="1000.0" lower="-0.50000" upper="0.50000" velocity="0.5"/>		
        <dynamics damping="1.0" friction="0.0001"/>
    </joint>
    <joint name="WRJ0y" type="prismatic">
        <parent link="base"/>
        <child link="palm"/>
        <origin xyz="0.0 0.0 0.0"/>
        <axis xyz="0 1 0"/>
        <limit effort="1000.0" lower="-0.50000" upper="0.50000" velocity="0.5"/>		
        <dynamics damping="1.0" friction="0.0001"/>
    </joint>
    <joint name="WRJ0z" type="prismatic">
        <parent link="base"/>
        <child link="palm"/>
        <origin xyz="0.0 0.0 0.0"/>
        <axis xyz="0 0 1"/>
        <limit effort="1000.0" lower="-0.50000" upper="0.50000" velocity="0.5"/>		
        <dynamics damping="1.0" friction="0.0001"/>
    </joint>
    <joint name="WRJ0rx" type="revolute">
        <parent link="base"/>
        <child link="palm"/>
        <origin xyz="0.0 0.0 0.0"/>
        <axis xyz="1 0 0"/>
        <limit effort="1000.0" lower="-0.50000" upper="0.50000" velocity="0.5"/>		
        <dynamics damping="1.0" friction="0.0001"/>
    </joint>
    <joint name="WRJ0ry" type="revolute">
        <parent link="base"/>
        <child link="palm"/>
        <origin xyz="0.0 0.0 0.0"/>
        <axis xyz="0 1 0"/>
        <limit effort="1000.0" lower="-0.50000" upper="0.50000" velocity="0.5"/>		
        <dynamics damping="1.0" friction="0.0001"/>
    </joint>
    <joint name="WRJ0rz" type="revolute">
        <parent link="base"/>
        <child link="palm"/>
        <origin xyz="0.0 0.0 0.0"/>
        <axis xyz="0 0 1"/>
        <limit effort="1000.0" lower="-0.50000" upper="0.50000" velocity="0.5"/>		
        <dynamics damping="1.0" friction="0.0001"/>
    </joint>


     <!-- FF -->
    <link name="fffixed">
        <visual>
            <origin rpy="0 0 0.0" xyz="0 0 0"/>
            <geometry>
                <mesh filename="meshes/ffprox_norm2.stl" scale="1 1 1"/>
            </geometry>
        </visual>
        <visual>
            <origin rpy="0 0 0.0" xyz="0 0 0"/>
            <geometry>
                <mesh filename="meshes/ffmiddle_norm2.stl" scale="1 1 1"/>
            </geometry>
        </visual>
        <visual>
            <origin rpy="0 0 0.0" xyz="0 0 0"/>
            <geometry>
                <mesh filename="meshes/ffdist_norm2.stl" scale="1 1 1"/>
            </geometry>
        </visual>
        <inertial>
            <origin rpy="0.00000 -0.00000 0.00000" xyz="0.00000 0.00000 0.00000"/>
            <mass value="0.00647"/>
            <inertia ixx="0.00000" ixy="0" ixz="0" iyy="0.00000" iyz="0" izz="0.00000"/>
        </inertial>
    </link>
    <!-- Fix Finger joint -->
    <joint name="Palm_FFJ2" type="fixed">
        <parent link="palm"/>
        <child link="fffixed"/>
        <origin xyz="0.0 0.0 0.0"/>
    </joint>


    <link name="ffproximal">
        <collision>
          <origin rpy="1.99869 1.42705 1.86385" xyz="-0.016115 0.0021222 0.000967899"/>
          <geometry>
            <capsule length="0.03257" radius="0.0075"/>
          </geometry>
       </collision>
        <inertial>
            <origin rpy="0.00000 -0.00000 0.00000" xyz="0.00000 0.00000 0.00000"/>
            <mass value="0.00647"/>
            <inertia ixx="0.00000" ixy="0" ixz="0" iyy="0.00000" iyz="0" izz="0.00000"/>
        </inertial>
    </link>
    <link name="link_ff_pm_y">
        <inertial>
            <origin rpy="0.00000 -0.00000 0.00000" xyz="0.00000 0.00000 0.00000"/>
            <mass value="0.00000"/>
            <inertia ixx="0.00000" ixy="0" ixz="0" iyy="0.00000" iyz="0" izz="0.00000"/>
        </inertial>
    </link>
    <link name="link_ff_pm_z">
        <inertial>
            <origin rpy="0.00000 -0.00000 0.00000" xyz="0.00000 0.00000 0.00000"/>
            <mass value="0.00000"/>
            <inertia ixx="0.00000" ixy="0" ixz="0" iyy="0.00000" iyz="0" izz="0.00000"/>
        </inertial>
    </link>
    <!-- FF2 proximal joint -->
    <joint name="FFJ2" type="revolute">
        <parent link="fffixed"/>
        <child link="ffproximal"/>
        <origin xyz="-0.0854947 -0.00507511 0.0193252"/>
        <axis xyz="1 0 0"/>
        <limit effort="1000.0" lower="-0.50000" upper="0.50000" velocity="0.5"/>
        <dynamics damping="1.0" friction="0.0001"/>
    </joint>
    <joint name="FFJ2_y" type="revolute">
        <parent link="ffproximal"/>
        <child link="link_ff_pm_y"/>
        <origin xyz="0 0 0"/>
        <axis xyz="0 1 0"/>
        <limit effort="1000.0" lower="-0.50000" upper="0.50000" velocity="0.5"/>
        <dynamics damping="1.0" friction="0.0001"/>
    </joint>
    <joint name="FFJ2_z" type="revolute">
        <parent link="link_ff_pm_y"/>
        <child link="link_ff_pm_z"/>
        <origin xyz="0 0 0"/>
        <axis xyz="0 0 1"/>
        <limit effort="1000.0" lower="-0.50000" upper="0.50000" velocity="0.5"/>
        <dynamics damping="1.0" friction="0.0001"/>
    </joint>

    <link name="ffmiddle">
        <collision>
          <origin rpy="-1.40722 1.51399 -1.35143" xyz="-0.0109464 -0.000614176 -0.000101378"/>
          <geometry>
            <capsule length="0.02193" radius="0.0075"/>
          </geometry>
       </collision>
        <inertial>
            <origin rpy="0.00000 -0.00000 0.00000" xyz="0.00000 0.00000 0.00000"/>
            <mass value="0.00647"/>
            <inertia ixx="0.00000" ixy="0" ixz="0" iyy="0.00000" iyz="0" izz="0.00000"/>
        </inertial>
    </link>
    <link name="link_ff_md_y">
        <inertial>
            <origin rpy="0.00000 -0.00000 0.00000" xyz="0.00000 0.00000 0.00000"/>
            <mass value="0.00000"/>
            <inertia ixx="0.00000" ixy="0" ixz="0" iyy="0.00000" iyz="0" izz="0.00000"/>
        </inertial>
    </link>
    <link name="link_ff_md_z">
        <inertial>
            <origin rpy="0.00000 -0.00000 0.00000" xyz="0.00000 0.00000 0.00000"/>
            <mass value="0.00000"/>
            <inertia ixx="0.00000" ixy="0" ixz="0" iyy="0.00000" iyz="0" izz="0.00000"/>
        </inertial>
    </link>
    <!-- FF1 joint -->
    <joint name="FFJ1" type="revolute">
        <parent link="link_ff_pm_z"/>
        <child link="ffmiddle"/>
        <origin xyz="-0.03223 0.0042444 0.0019358"/>
        <axis xyz="1 0 0"/>
        <limit effort="1000.0" lower="-0.50000" upper="0.50000" velocity="0.5"/>
        <dynamics damping="1.0" friction="0.0001"/>
    </joint>
    <joint name="FFJ1_y" type="revolute">
        <parent link="ffmiddle"/>
        <child link="link_ff_md_y"/>
        <origin xyz="0.0 0.0 0.0"/>
        <axis xyz="0 1 0"/>
        <limit effort="1000.0" lower="-0.50000" upper="0.50000" velocity="0.5"/>
        <dynamics damping="1.0" friction="0.0001"/>
    </joint>
    <joint name="FFJ1_z" type="revolute">
        <parent link="link_ff_md_y"/>
        <child link="link_ff_md_z"/>
        <origin xyz="0.0 0.0 0.0"/>
        <axis xyz="0 0 1"/>
        <limit effort="1000.0" lower="-0.50000" upper="0.50000" velocity="0.5"/>
        <dynamics damping="1.0" friction="0.0001"/>
    </joint>

    <link name="ffdistal">
        <collision>
          <origin rpy="2.99663 1.41120 2.97154" xyz="-0.0113096 0.000262979 0.00180133"/>
          <geometry>
            <capsule length="0.02291" radius="0.0075"/>
          </geometry>
       </collision>
        <inertial>
            <origin rpy="0.00000 -0.00000 0.00000" xyz="0.00000 0.00000 0.00000"/>
            <mass value="0.00647"/>
            <inertia ixx="0.00000" ixy="0" ixz="0" iyy="0.00000" iyz="0" izz="0.00000"/>
        </inertial>
    </link>
    <link name="link_ff_dd_y">
        <inertial>
            <origin rpy="0.00000 -0.00000 0.00000" xyz="0.00000 0.00000 0.00000"/>
            <mass value="0.00000"/>
            <inertia ixx="0.00000" ixy="0" ixz="0" iyy="0.00000" iyz="0" izz="0.00000"/>
        </inertial>
    </link>
    <link name="link_ff_dd_z">
        <inertial>
            <origin rpy="0.00000 -0.00000 0.00000" xyz="0.00000 0.00000 0.00000"/>
            <mass value="0.00000"/>
            <inertia ixx="0.00000" ixy="0" ixz="0" iyy="0.00000" iyz="0" izz="0.00000"/>
        </inertial>
    </link>
    <!-- FF1 joint -->
    <joint name="FFJ0" type="revolute">
        <parent link="link_ff_md_z"/>
        <child link="ffdistal"/>
        <origin xyz="-0.02189 -0.00123 -0.00020"/>
        <axis xyz="1 0 0"/>
        <limit effort="1000.0" lower="-0.50000" upper="0.50000" velocity="0.5"/>
        <dynamics damping="1.0" friction="0.0001"/>
    </joint>
    <joint name="FFJ0_y" type="revolute">
        <parent link="ffdistal"/>
        <child link="link_ff_dd_y"/>
        <origin xyz="0.0 0.0 0.0"/>
        <axis xyz="0 1 0"/>
        <limit effort="1000.0" lower="-0.50000" upper="0.50000" velocity="0.5"/>
        <dynamics damping="1.0" friction="0.0001"/>
    </joint>
    <joint name="FFJ0_z" type="revolute">
        <parent link="link_ff_dd_y"/>
        <child link="link_ff_dd_z"/>
        <origin xyz="0.0 0.0 0.0"/>
        <axis xyz="0 0 1"/>
        <limit effort="1000.0" lower="-0.50000" upper="0.50000" velocity="0.5"/>
        <dynamics damping="1.0" friction="0.0001"/>
    </joint>

    <!-- MF -->
    <link name="mffixed">
        <visual>
            <origin rpy="0 0 0.0" xyz="0 0 0"/>
            <geometry>
                <mesh filename="meshes/mfprox_norm2.stl" scale="1 1 1"/>
            </geometry>
        </visual>
        <visual>
            <origin rpy="0 0 0.0" xyz="0 0 0"/>
            <geometry>
                <mesh filename="meshes/mfmiddle_norm2.stl" scale="1 1 1"/>
            </geometry>
        </visual>
        <visual>
            <origin rpy="0 0 0.0" xyz="0 0 0"/>
            <geometry>
                <mesh filename="meshes/mfdist_norm2.stl" scale="1 1 1"/>
            </geometry>
        </visual>
        <inertial>
            <origin rpy="0.00000 -0.00000 0.00000" xyz="0.00000 0.00000 0.00000"/>
            <mass value="0.00647"/>
            <inertia ixx="0.00000" ixy="0" ixz="0" iyy="0.00000" iyz="0" izz="0.00000"/>
        </inertial>
    </link>
    <!-- Fix Finger joint -->
    <joint name="Palm_MFJ2" type="fixed">
        <parent link="palm"/>
        <child link="mffixed"/>
        <origin xyz="0.0 0.0 0.0"/>
    </joint>


    <link name="mfproximal">
        <collision>
          <origin rpy="0.30429 1.37974 0.25169" xyz="-0.015276 0.000885268 -0.00281892"/>
          <geometry>
            <capsule length="0.03112" radius="0.0075"/>
          </geometry>
       </collision>
        <inertial>
            <origin rpy="0.00000 -0.00000 0.00000" xyz="0.00000 0.00000 0.00000"/>
            <mass value="0.00647"/>
            <inertia ixx="0.00000" ixy="0" ixz="0" iyy="0.00000" iyz="0" izz="0.00000"/>
        </inertial>
    </link>
    <link name="link_mf_pm_y">
        <inertial>
            <origin rpy="0.00000 -0.00000 0.00000" xyz="0.00000 0.00000 0.00000"/>
            <mass value="0.00000"/>
            <inertia ixx="0.00000" ixy="0" ixz="0" iyy="0.00000" iyz="0" izz="0.00000"/>
        </inertial>
    </link>
    <link name="link_mf_pm_z">
        <inertial>
            <origin rpy="0.00000 -0.00000 0.00000" xyz="0.00000 0.00000 0.00000"/>
            <mass value="0.00000"/>
            <inertia ixx="0.00000" ixy="0" ixz="0" iyy="0.00000" iyz="0" izz="0.00000"/>
        </inertial>
    </link>
    <!-- MF2 proximal joint -->
    <joint name="MFJ2" type="revolute">
        <parent link="mffixed"/>
        <child link="mfproximal"/>
        <origin xyz="-0.0917039 -0.00186778 -0.00333364"/>
        <axis xyz="1 0 0"/>
        <limit effort="1000.0" lower="-0.50000" upper="0.50000" velocity="0.5"/>
        <dynamics damping="1.0" friction="0.0001"/>
    </joint>
    <joint name="MFJ2_y" type="revolute">
        <parent link="mfproximal"/>
        <child link="link_mf_pm_y"/>
        <origin xyz="-0.0917039 -0.00186778 -0.00333364"/>
        <axis xyz="0 1 0"/>
        <limit effort="1000.0" lower="-0.50000" upper="0.50000" velocity="0.5"/>
        <dynamics damping="1.0" friction="0.0001"/>
    </joint>
    <joint name="MFJ2_z" type="revolute">
        <parent link="link_mf_pm_y"/>
        <child link="link_mf_pm_z"/>
        <origin xyz="-0.0917039 -0.00186778 -0.00333364"/>
        <axis xyz="0 0 1"/>
        <limit effort="1000.0" lower="-0.50000" upper="0.50000" velocity="0.5"/>
        <dynamics damping="1.0" friction="0.0001"/>
    </joint>

    <link name="mfmiddle">
        <collision>
          <origin rpy="-0.30066 1.39216 -0.25180" xyz="-0.0112555 -0.000601872 -0.00194118"/>
          <geometry>
            <capsule length="0.02287" radius="0.0075"/>
          </geometry>
       </collision>
        <inertial>
            <origin rpy="0.00000 -0.00000 0.00000" xyz="0.00000 0.00000 0.00000"/>
            <mass value="0.00647"/>
            <inertia ixx="0.00000" ixy="0" ixz="0" iyy="0.00000" iyz="0" izz="0.00000"/>
        </inertial>
    </link>
    <link name="link_mf_md_y">
        <inertial>
            <origin rpy="0.00000 -0.00000 0.00000" xyz="0.00000 0.00000 0.00000"/>
            <mass value="0.00000"/>
            <inertia ixx="0.00000" ixy="0" ixz="0" iyy="0.00000" iyz="0" izz="0.00000"/>
        </inertial>
    </link>
    <link name="link_mf_md_z">
        <inertial>
            <origin rpy="0.00000 -0.00000 0.00000" xyz="0.00000 0.00000 0.00000"/>
            <mass value="0.00000"/>
            <inertia ixx="0.00000" ixy="0" ixz="0" iyy="0.00000" iyz="0" izz="0.00000"/>
        </inertial>
    </link>
    <!-- MF1 joint -->
    <joint name="MFJ1" type="revolute">
        <parent link="mfproximal"/>
        <child link="mfmiddle"/>
        <origin xyz="-0.0305521 0.00177054 -0.00563785"/>
        <axis xyz="1 0 0"/>
        <limit effort="1000.0" lower="-0.50000" upper="0.50000" velocity="0.5"/>
        <dynamics damping="1.0" friction="0.0001"/>
    </joint>
    <joint name="MFJ1_y" type="revolute">
        <parent link="mfmiddle"/>
        <child link="link_mf_md_y"/>
        <origin xyz="-0.0305521 0.00177054 -0.00563785"/>
        <axis xyz="0 1 0"/>
        <limit effort="1000.0" lower="-0.50000" upper="0.50000" velocity="0.5"/>
        <dynamics damping="1.0" friction="0.0001"/>
    </joint>
    <joint name="MFJ1_z" type="revolute">
        <parent link="mfproximal"/>
        <child link="mfmiddle"/>
        <origin xyz="-0.0305521 0.00177054 -0.00563785"/>
        <axis xyz="0 0 1"/>
        <limit effort="1000.0" lower="-0.50000" upper="0.50000" velocity="0.5"/>
        <dynamics damping="1.0" friction="0.0001"/>
    </joint>

    <link name="mfdistal">
        <collision>
          <origin rpy="-0.00758 1.36655 -0.00617" xyz="-0.0125493 -1.9697e-05 -0.00259927"/>
          <geometry>
            <capsule length="0.02563" radius="0.0075"/>
          </geometry>
       </collision>
        <inertial>
            <origin rpy="0.00000 -0.00000 0.00000" xyz="0.00000 0.00000 0.00000"/>
            <mass value="0.00647"/>
            <inertia ixx="0.00000" ixy="0" ixz="0" iyy="0.00000" iyz="0" izz="0.00000"/>
        </inertial>
    </link>
    <link name="link_mf_dd_y">
        <inertial>
            <origin rpy="0.00000 -0.00000 0.00000" xyz="0.00000 0.00000 0.00000"/>
            <mass value="0.00000"/>
            <inertia ixx="0.00000" ixy="0" ixz="0" iyy="0.00000" iyz="0" izz="0.00000"/>
        </inertial>
    </link>
    <link name="link_mf_dd_z">
        <inertial>
            <origin rpy="0.00000 -0.00000 0.00000" xyz="0.00000 0.00000 0.00000"/>
            <mass value="0.00000"/>
            <inertia ixx="0.00000" ixy="0" ixz="0" iyy="0.00000" iyz="0" izz="0.00000"/>
        </inertial>
    </link>
    <!-- MF0 joint -->
    <joint name="MFJ0" type="revolute">
        <parent link="mfmiddle"/>
        <child link="mfdistal"/>
        <origin xyz="-0.0225109 -0.00120374 -0.00388236"/>
        <axis xyz="1 0 0"/>
        <limit effort="1000.0" lower="-0.50000" upper="0.50000" velocity="0.5"/>
        <dynamics damping="1.0" friction="0.0001"/>
    </joint>
    <joint name="MFJ0_y" type="revolute">
        <parent link="mfmiddle"/>
        <child link="mfdistal"/>
        <origin xyz="-0.0225109 -0.00120374 -0.00388236"/>
        <axis xyz="0 1 0"/>
        <limit effort="1000.0" lower="-0.50000" upper="0.50000" velocity="0.5"/>
        <dynamics damping="1.0" friction="0.0001"/>
    </joint>
    <joint name="MFJ0_z" type="revolute">
        <parent link="mfmiddle"/>
        <child link="mfdistal"/>
        <origin xyz="-0.0225109 -0.00120374 -0.00388236"/>
        <axis xyz="0 0 1"/>
        <limit effort="1000.0" lower="-0.50000" upper="0.50000" velocity="0.5"/>
        <dynamics damping="1.0" friction="0.0001"/>
    </joint>

    <!-- RF -->
    <link name="rffixed">
        <visual>
            <origin rpy="0 0 0.0" xyz="0 0 0"/>
            <geometry>
                <mesh filename="meshes/rfprox_norm2.stl" scale="1 1 1"/>
            </geometry>
        </visual>
        <visual>
            <origin rpy="0 0 0.0" xyz="0 0 0"/>
            <geometry>
                <mesh filename="meshes/rfmiddle_norm2.stl" scale="1 1 1"/>
            </geometry>
        </visual>
        <visual>
            <origin rpy="0 0 0.0" xyz="0 0 0"/>
            <geometry>
                <mesh filename="meshes/rfdist_norm2.stl" scale="1 1 1"/>
            </geometry>
        </visual>
        <inertial>
            <origin rpy="0.00000 -0.00000 0.00000" xyz="0.00000 0.00000 0.00000"/>
            <mass value="0.00647"/>
            <inertia ixx="0.00000" ixy="0" ixz="0" iyy="0.00000" iyz="0" izz="0.00000"/>
        </inertial>
    </link>

    <!-- Fix Finger joint -->
    <joint name="Palm_RFJ2" type="fixed">
        <parent link="palm"/>
        <child link="rffixed"/>
        <origin xyz="0.0 0.0 0.0"/>
    </joint>


    <link name="rfproximal">
        <collision>
          <origin rpy="0.33491 1.37351 0.27543" xyz="-0.0138757 0.000911628 -0.00261948"/>
          <geometry>
            <capsule length="0.02830" radius="0.0075"/>
          </geometry>
       </collision>
        <inertial>
            <origin rpy="0.00000 -0.00000 0.00000" xyz="0.00000 0.00000 0.00000"/>
            <mass value="0.00647"/>
            <inertia ixx="0.00000" ixy="0" ixz="0" iyy="0.00000" iyz="0" izz="0.00000"/>
        </inertial>
    </link>
    <link name="link_rf_pm_y">
        <inertial>
            <origin rpy="0.00000 -0.00000 0.00000" xyz="0.00000 0.00000 0.00000"/>
            <mass value="0.00000"/>
            <inertia ixx="0.00000" ixy="0" ixz="0" iyy="0.00000" iyz="0" izz="0.00000"/>
        </inertial>
    </link>
    <link name="link_rf_pm_z">
        <inertial>
            <origin rpy="0.00000 -0.00000 0.00000" xyz="0.00000 0.00000 0.00000"/>
            <mass value="0.00000"/>
            <inertia ixx="0.00000" ixy="0" ixz="0" iyy="0.00000" iyz="0" izz="0.00000"/>
        </inertial>
    </link>
    <!-- RF2 proximal joint -->
    <joint name="RFJ2" type="revolute">
        <parent link="rffixed"/>
        <child link="rfproximal"/>
        <origin xyz="-0.0793526 -0.00417752 -0.0249895"/>
        <axis xyz="1 0 0"/>
        <limit effort="1000.0" lower="-0.50000" upper="0.50000" velocity="0.5"/>
        <dynamics damping="1.0" friction="0.0001"/>
    </joint>
    <joint name="RFJ2_y" type="revolute">
        <parent link="rffixed"/>
        <child link="rfproximal"/>
        <origin xyz="-0.0793526 -0.00417752 -0.0249895"/>
        <axis xyz="0 1 0"/>
        <limit effort="1000.0" lower="-0.50000" upper="0.50000" velocity="0.5"/>
        <dynamics damping="1.0" friction="0.0001"/>
    </joint>
    <joint name="RFJ2_z" type="revolute">
        <parent link="rffixed"/>
        <child link="rfproximal"/>
        <origin xyz="-0.0793526 -0.00417752 -0.0249895"/>
        <axis xyz="0 0 1"/>
        <limit effort="1000.0" lower="-0.50000" upper="0.50000" velocity="0.5"/>
        <dynamics damping="1.0" friction="0.0001"/>
    </joint>

    <link name="rfmiddle">
        <collision>
          <origin rpy="-0.21975 1.24718 -0.15838" xyz="-0.0115695 -0.000845882 -0.0037872"/>
          <geometry>
            <capsule length="0.02441" radius="0.0075"/>
          </geometry>
       </collision>
        <inertial>
            <origin rpy="0.00000 -0.00000 0.00000" xyz="0.00000 0.00000 0.00000"/>
            <mass value="0.00647"/>
            <inertia ixx="0.00000" ixy="0" ixz="0" iyy="0.00000" iyz="0" izz="0.00000"/>
        </inertial>
    </link>
    <link name="link_rf_md_y">
        <inertial>
            <origin rpy="0.00000 -0.00000 0.00000" xyz="0.00000 0.00000 0.00000"/>
            <mass value="0.00000"/>
            <inertia ixx="0.00000" ixy="0" ixz="0" iyy="0.00000" iyz="0" izz="0.00000"/>
        </inertial>
    </link>
    <link name="link_rf_md_z">
        <inertial>
            <origin rpy="0.00000 -0.00000 0.00000" xyz="0.00000 0.00000 0.00000"/>
            <mass value="0.00000"/>
            <inertia ixx="0.00000" ixy="0" ixz="0" iyy="0.00000" iyz="0" izz="0.00000"/>
        </inertial>
    </link>
    <!-- RF1 joint -->
    <joint name="RFJ1" type="revolute">
        <parent link="rfproximal"/>
        <child link="rfmiddle"/>
        <origin xyz="-0.0277513 0.00182326 -0.00523897"/>
        <axis xyz="1 0 0"/>
        <limit effort="1000.0" lower="-0.50000" upper="0.50000" velocity="0.5"/>
        <dynamics damping="1.0" friction="0.0001"/>
    </joint>
    <joint name="RFJ1_y" type="revolute">
        <parent link="rfproximal"/>
        <child link="rfmiddle"/>
        <origin xyz="-0.0277513 0.00182326 -0.00523897"/>
        <axis xyz="0 1 0"/>
        <limit effort="1000.0" lower="-0.50000" upper="0.50000" velocity="0.5"/>
        <dynamics damping="1.0" friction="0.0001"/>
    </joint>
    <joint name="RFJ1_z" type="revolute">
        <parent link="rfproximal"/>
        <child link="rfmiddle"/>
        <origin xyz="-0.0277513 0.00182326 -0.00523897"/>
        <axis xyz="0 0 1"/>
        <limit effort="1000.0" lower="-0.50000" upper="0.50000" velocity="0.5"/>
        <dynamics damping="1.0" friction="0.0001"/>
    </joint>

    <link name="rfdistal">
        <collision>
          <origin rpy="0.52073 1.21114 0.36480" xyz="-0.0108901 0.0020372 -0.00355203"/>
          <geometry>
            <capsule length="0.02327" radius="0.0075"/>
          </geometry>
       </collision>
        <inertial>
            <origin rpy="0.00000 -0.00000 0.00000" xyz="0.00000 0.00000 0.00000"/>
            <mass value="0.00647"/>
            <inertia ixx="0.00000" ixy="0" ixz="0" iyy="0.00000" iyz="0" izz="0.00000"/>
        </inertial>
    </link>
    <link name="link_rf_dd_y">
        <inertial>
            <origin rpy="0.00000 -0.00000 0.00000" xyz="0.00000 0.00000 0.00000"/>
            <mass value="0.00000"/>
            <inertia ixx="0.00000" ixy="0" ixz="0" iyy="0.00000" iyz="0" izz="0.00000"/>
        </inertial>
    </link>
    <link name="link_rf_dd_z">
        <inertial>
            <origin rpy="0.00000 -0.00000 0.00000" xyz="0.00000 0.00000 0.00000"/>
            <mass value="0.00000"/>
            <inertia ixx="0.00000" ixy="0" ixz="0" iyy="0.00000" iyz="0" izz="0.00000"/>
        </inertial>
    </link>
    <!-- RF0 joint -->
    <joint name="RFJ0" type="revolute">
        <parent link="rfmiddle"/>
        <child link="rfdistal"/>
        <origin xyz="-0.0231389 -0.00169176 -0.00757441"/>
        <axis xyz="1 0 0"/>
        <limit effort="1000.0" lower="-0.50000" upper="0.50000" velocity="0.5"/>
        <dynamics damping="1.0" friction="0.0001"/>
    </joint>
    <joint name="RFJ0_y" type="revolute">
        <parent link="rfmiddle"/>
        <child link="rfdistal"/>
        <origin xyz="-0.0231389 -0.00169176 -0.00757441"/>
        <axis xyz="0 1 0"/>
        <limit effort="1000.0" lower="-0.50000" upper="0.50000" velocity="0.5"/>
        <dynamics damping="1.0" friction="0.0001"/>
    </joint>
    <joint name="RFJ0_z" type="revolute">
        <parent link="rfmiddle"/>
        <child link="rfdistal"/>
        <origin xyz="-0.0231389 -0.00169176 -0.00757441"/>
        <axis xyz="0 0 1"/>
        <limit effort="1000.0" lower="-0.50000" upper="0.50000" velocity="0.5"/>
        <dynamics damping="1.0" friction="0.0001"/>
    </joint>

     <!-- LF -->
    <link name="lffixed">
        <inertial>
            <origin rpy="0.00000 -0.00000 0.00000" xyz="0.00000 0.00000 0.00000"/>
            <mass value="0.00647"/>
            <inertia ixx="0.00000" ixy="0" ixz="0" iyy="0.00000" iyz="0" izz="0.00000"/>
        </inertial>
        <visual>
            <origin rpy="0 0 0.0" xyz="0 0 0"/>
            <geometry>
                <mesh filename="meshes/lfprox_norm2.stl" scale="1 1 1"/>
            </geometry>
        </visual>
        <visual>
            <origin rpy="0 0 0.0" xyz="0 0 0"/>
            <geometry>
                <mesh filename="meshes/lfmiddle_norm2.stl" scale="1 1 1"/>
            </geometry>
        </visual>
        <visual>
            <origin rpy="0 0 0.0" xyz="0 0 0"/>
            <geometry>
                <mesh filename="meshes/lfdist_norm2.stl" scale="1 1 1"/>
            </geometry>
        </visual>
    </link>
    <!-- Fix Finger joint -->
    <joint name="Palm_LFJ2" type="fixed">
        <parent link="palm"/>
        <child link="lffixed"/>
        <origin xyz="0.0 0.0 0.0"/>
    </joint>


    <link name="lfproximal">
        <collision>
          <origin rpy="0.03545 0.92106 0.01759" xyz="-0.00813489 0.000219065 -0.00617687"/>
          <geometry>
            <capsule length="0.02043" radius="0.0075"/>
          </geometry>
       </collision>
        <inertial>
            <origin rpy="0.00000 -0.00000 0.00000" xyz="0.00000 0.00000 0.00000"/>
            <mass value="0.00647"/>
            <inertia ixx="0.00000" ixy="0" ixz="0" iyy="0.00000" iyz="0" izz="0.00000"/>
        </inertial>
    </link>
    <link name="link_lf_pm_y">
        <inertial>
            <origin rpy="0.00000 -0.00000 0.00000" xyz="0.00000 0.00000 0.00000"/>
            <mass value="0.00000"/>
            <inertia ixx="0.00000" ixy="0" ixz="0" iyy="0.00000" iyz="0" izz="0.00000"/>
        </inertial>
    </link>
    <link name="link_lf_pm_z">
        <inertial>
            <origin rpy="0.00000 -0.00000 0.00000" xyz="0.00000 0.00000 0.00000"/>
            <mass value="0.00000"/>
            <inertia ixx="0.00000" ixy="0" ixz="0" iyy="0.00000" iyz="0" izz="0.00000"/>
        </inertial>
    </link>
    <!-- LF2 proximal joint -->
    <joint name="LFJ2" type="revolute">
        <parent link="lffixed"/>
        <child link="lfproximal"/>
        <origin xyz="-0.067051 -0.00936936 -0.0405877"/>
        <axis xyz="1 0 0"/>
        <limit effort="1000.0" lower="-0.50000" upper="0.50000" velocity="0.5"/>
        <dynamics damping="1.0" friction="0.0001"/>
    </joint>
    <joint name="LFJ2_y" type="revolute">
        <parent link="lffixed"/>
        <child link="lfproximal"/>
        <origin xyz="-0.067051 -0.00936936 -0.0405877"/>
        <axis xyz="0 1 0"/>
        <limit effort="1000.0" lower="-0.50000" upper="0.50000" velocity="0.5"/>
        <dynamics damping="1.0" friction="0.0001"/>
    </joint>
    <joint name="LFJ2_z" type="revolute">
        <parent link="lffixed"/>
        <child link="lfproximal"/>
        <origin xyz="-0.067051 -0.00936936 -0.0405877"/>
        <axis xyz="0 0 1"/>
        <limit effort="1000.0" lower="-0.50000" upper="0.50000" velocity="0.5"/>
        <dynamics damping="1.0" friction="0.0001"/>
    </joint>

    <link name="lfmiddle">
        <collision>
          <origin rpy="-0.07079 0.97129 -0.03738" xyz="-0.00764547 -0.000369589 -0.00521187"/>
          <geometry>
            <capsule length="0.01852" radius="0.0075"/>
          </geometry>
       </collision>
        <inertial>
            <origin rpy="0.00000 -0.00000 0.00000" xyz="0.00000 0.00000 0.00000"/>
            <mass value="0.00647"/>
            <inertia ixx="0.00000" ixy="0" ixz="0" iyy="0.00000" iyz="0" izz="0.00000"/>
        </inertial>
    </link>
    <link name="link_lf_md_y">
        <inertial>
            <origin rpy="0.00000 -0.00000 0.00000" xyz="0.00000 0.00000 0.00000"/>
            <mass value="0.00000"/>
            <inertia ixx="0.00000" ixy="0" ixz="0" iyy="0.00000" iyz="0" izz="0.00000"/>
        </inertial>
    </link>
    <link name="link_lf_md_z">
        <inertial>
            <origin rpy="0.00000 -0.00000 0.00000" xyz="0.00000 0.00000 0.00000"/>
            <mass value="0.00000"/>
            <inertia ixx="0.00000" ixy="0" ixz="0" iyy="0.00000" iyz="0" izz="0.00000"/>
        </inertial>
    </link>
    <!-- LF1 joint -->
    <joint name="LFJ1" type="revolute">
        <parent link="lfproximal"/>
        <child link="lfmiddle"/>
        <origin xyz="-0.0162698 0.00043813 -0.0123537"/>
        <axis xyz="1 0 0"/>
        <limit effort="1000.0" lower="-0.50000" upper="0.50000" velocity="0.5"/>
        <dynamics damping="1.0" friction="0.0001"/>
    </joint>
    <joint name="LFJ1_y" type="revolute">
        <parent link="lfproximal"/>
        <child link="lfmiddle"/>
        <origin xyz="-0.0162698 0.00043813 -0.0123537"/>
        <axis xyz="0 1 0"/>
        <limit effort="1000.0" lower="-0.50000" upper="0.50000" velocity="0.5"/>
        <dynamics damping="1.0" friction="0.0001"/>
    </joint>
    <joint name="LFJ1_z" type="revolute">
        <parent link="lfproximal"/>
        <child link="lfmiddle"/>
        <origin xyz="-0.0162698 0.00043813 -0.0123537"/>
        <axis xyz="0 0 1"/>
        <limit effort="1000.0" lower="-0.50000" upper="0.50000" velocity="0.5"/>
        <dynamics damping="1.0" friction="0.0001"/>
    </joint>

    <link name="lfdistal">
        <collision>
          <origin rpy="0.21103 1.00171 0.11582" xyz="-0.00829585 0.00111158 -0.00518895"/>
          <geometry>
            <capsule length="0.01970" radius="0.0075"/>
          </geometry>
       </collision>
        <inertial>
            <origin rpy="0.00000 -0.00000 0.00000" xyz="0.00000 0.00000 0.00000"/>
            <mass value="0.00647"/>
            <inertia ixx="0.00000" ixy="0" ixz="0" iyy="0.00000" iyz="0" izz="0.00000"/>
        </inertial>
    </link>
    <link name="link_lf_dd_y">
        <inertial>
            <origin rpy="0.00000 -0.00000 0.00000" xyz="0.00000 0.00000 0.00000"/>
            <mass value="0.00000"/>
            <inertia ixx="0.00000" ixy="0" ixz="0" iyy="0.00000" iyz="0" izz="0.00000"/>
        </inertial>
    </link>
    <link name="link_lf_dd_z">
        <inertial>
            <origin rpy="0.00000 -0.00000 0.00000" xyz="0.00000 0.00000 0.00000"/>
            <mass value="0.00000"/>
            <inertia ixx="0.00000" ixy="0" ixz="0" iyy="0.00000" iyz="0" izz="0.00000"/>
        </inertial>
    </link>
    <!-- LF0 joint -->
    <joint name="LFJ0" type="revolute">
        <parent link="lfmiddle"/>
        <child link="lfdistal"/>
        <origin xyz="-0.0152909 -0.000739178 -0.0104237"/>
        <axis xyz="1 0 0"/>
        <limit effort="1000.0" lower="-0.50000" upper="0.50000" velocity="0.5"/>
        <dynamics damping="1.0" friction="0.0001"/>
    </joint>
    <joint name="LFJ0_y" type="revolute">
        <parent link="lfmiddle"/>
        <child link="lfdistal"/>
        <origin xyz="-0.0152909 -0.000739178 -0.0104237"/>
        <axis xyz="0 1 0"/>
        <limit effort="1000.0" lower="-0.50000" upper="0.50000" velocity="0.5"/>
        <dynamics damping="1.0" friction="0.0001"/>
    </joint>
    <joint name="LFJ0_z" type="revolute">
        <parent link="lfmiddle"/>
        <child link="lfdistal"/>
        <origin xyz="-0.0152909 -0.000739178 -0.0104237"/>
        <axis xyz="0 0 1"/>
        <limit effort="1000.0" lower="-0.50000" upper="0.50000" velocity="0.5"/>
        <dynamics damping="1.0" friction="0.0001"/>
    </joint>


    <!-- TH -->
    <link name="thfixed">
        <inertial>
            <origin rpy="0.00000 -0.00000 0.00000" xyz="0.00000 0.00000 0.00000"/>
            <mass value="0.00647"/>
            <inertia ixx="0.00000" ixy="0" ixz="0" iyy="0.00000" iyz="0" izz="0.00000"/>
        </inertial>
        <visual>
            <origin rpy="0 0 0.0" xyz="0 0 0"/>
            <geometry>
                <mesh filename="meshes/thprox_norm2.stl" scale="1 1 1"/>
            </geometry>
        </visual>
        <visual>
            <origin rpy="0 0 0.0" xyz="0 0 0"/>
            <geometry>
                <mesh filename="meshes/thmiddle_norm2.stl" scale="1 1 1"/>
            </geometry>
        </visual>
        <visual>
            <origin rpy="0 0 0.0" xyz="0 0 0"/>
            <geometry>
                <mesh filename="meshes/thdist_norm2.stl" scale="1 1 1"/>
            </geometry>
        </visual>
    </link>
    <!-- Fix Finger joint -->
    <joint name="Palm_THJ2" type="fixed">
        <parent link="palm"/>
        <child link="thfixed"/>
        <origin xyz="0.0 0.0 0.0"/>
    </joint>


    <link name="thproximal">
        <collision>
          <origin rpy="3.13218 0.71707 3.11647" xyz="-0.00985257 0.000106405 0.0112997"/>
          <geometry>
            <capsule length="0.02998" radius="0.0075"/>
          </geometry>
       </collision>
        <inertial>
            <origin rpy="0.00000 -0.00000 0.00000" xyz="0.00000 0.00000 0.00000"/>
            <mass value="0.00647"/>
            <inertia ixx="0.00000" ixy="0" ixz="0" iyy="0.00000" iyz="0" izz="0.00000"/>
        </inertial>
    </link>
    <link name="link_th_pm_y">
        <inertial>
            <origin rpy="0.00000 -0.00000 0.00000" xyz="0.00000 0.00000 0.00000"/>
            <mass value="0.00000"/>
            <inertia ixx="0.00000" ixy="0" ixz="0" iyy="0.00000" iyz="0" izz="0.00000"/>
        </inertial>
    </link>
    <link name="link_th_pm_z">
        <inertial>
            <origin rpy="0.00000 -0.00000 0.00000" xyz="0.00000 0.00000 0.00000"/>
            <mass value="0.00000"/>
            <inertia ixx="0.00000" ixy="0" ixz="0" iyy="0.00000" iyz="0" izz="0.00000"/>
        </inertial>
    </link>
    <!-- TH2 proximal joint -->
    <joint name="THJ2" type="revolute">
        <parent link="thfixed"/>
        <child link="thproximal"/>
        <origin xyz="-0.0237422 -0.014157 0.0243549"/>
        <axis xyz="1 0 0"/>
        <limit effort="1000.0" lower="-0.50000" upper="0.50000" velocity="0.5"/>
        <dynamics damping="1.0" friction="0.0001"/>
    </joint>
    <joint name="THJ2_y" type="revolute">
        <parent link="thfixed"/>
        <child link="thproximal"/>
        <origin xyz="-0.0237422 -0.014157 0.0243549"/>
        <axis xyz="0 1 0"/>
        <limit effort="1000.0" lower="-0.50000" upper="0.50000" velocity="0.5"/>
        <dynamics damping="1.0" friction="0.0001"/>
    </joint>
    <joint name="THJ2_z" type="revolute">
        <parent link="thfixed"/>
        <child link="thproximal"/>
        <origin xyz="-0.0237422 -0.014157 0.0243549"/>
        <axis xyz="0 0 1"/>
        <limit effort="1000.0" lower="-0.50000" upper="0.50000" velocity="0.5"/>
        <dynamics damping="1.0" friction="0.0001"/>
    </joint>

    <link name="thmiddle">
        <collision>
          <origin rpy="-2.78744 0.95704 -2.47720" xyz="-0.0108762 -0.00265738 0.00718706"/>
          <geometry>
            <capsule length="0.02661" radius="0.0075"/>
          </geometry>
       </collision>
        <inertial>
            <origin rpy="0.00000 -0.00000 0.00000" xyz="0.00000 0.00000 0.00000"/>
            <mass value="0.00647"/>
            <inertia ixx="0.00000" ixy="0" ixz="0" iyy="0.00000" iyz="0" izz="0.00000"/>
        </inertial>
    </link>
    <link name="link_th_md_y">
        <inertial>
            <origin rpy="0.00000 -0.00000 0.00000" xyz="0.00000 0.00000 0.00000"/>
            <mass value="0.00000"/>
            <inertia ixx="0.00000" ixy="0" ixz="0" iyy="0.00000" iyz="0" izz="0.00000"/>
        </inertial>
    </link>
    <link name="link_th_md_z">
        <inertial>
            <origin rpy="0.00000 -0.00000 0.00000" xyz="0.00000 0.00000 0.00000"/>
            <mass value="0.00000"/>
            <inertia ixx="0.00000" ixy="0" ixz="0" iyy="0.00000" iyz="0" izz="0.00000"/>
        </inertial>
    </link>
    <!-- TH1 joint -->
    <joint name="THJ1" type="revolute">
        <parent link="thproximal"/>
        <child link="thmiddle"/>
        <origin xyz="-0.0197051 0.00021281 0.0225994"/>
        <axis xyz="1 0 0"/>
        <limit effort="1000.0" lower="-0.50000" upper="0.50000" velocity="0.5"/>
        <dynamics damping="1.0" friction="0.0001"/>
    </joint>
    <joint name="THJ1_y" type="revolute">
        <parent link="thproximal"/>
        <child link="thmiddle"/>
        <origin xyz="-0.0197051 0.00021281 0.0225994"/>
        <axis xyz="0 1 0"/>
        <limit effort="1000.0" lower="-0.50000" upper="0.50000" velocity="0.5"/>
        <dynamics damping="1.0" friction="0.0001"/>
    </joint>
    <joint name="THJ1_z" type="revolute">
        <parent link="thproximal"/>
        <child link="thmiddle"/>
        <origin xyz="-0.0197051 0.00021281 0.0225994"/>
        <axis xyz="0 0 1"/>
        <limit effort="1000.0" lower="-0.50000" upper="0.50000" velocity="0.5"/>
        <dynamics damping="1.0" friction="0.0001"/>
    </joint>

    <link name="thdistal">
    <collision>
      <origin rpy="-2.90231 0.92975 -2.67108" xyz="-0.013664 -0.00241645 0.00990511"/>
      <geometry>
        <capsule length="0.03410" radius="0.0075"/>
      </geometry>
   </collision>
    <inertial>
        <origin rpy="0.00000 -0.00000 0.00000" xyz="0.00000 0.00000 0.00000"/>
        <mass value="0.00647"/>
        <inertia ixx="0.00000" ixy="0" ixz="0" iyy="0.00000" iyz="0" izz="0.00000"/>
    </inertial>
    </link>
    <link name="link_th_dd_y">
        <inertial>
            <origin rpy="0.00000 -0.00000 0.00000" xyz="0.00000 0.00000 0.00000"/>
            <mass value="0.00000"/>
            <inertia ixx="0.00000" ixy="0" ixz="0" iyy="0.00000" iyz="0" izz="0.00000"/>
        </inertial>
    </link>
    <link name="link_th_dd_z">
        <inertial>
            <origin rpy="0.00000 -0.00000 0.00000" xyz="0.00000 0.00000 0.00000"/>
            <mass value="0.00000"/>
            <inertia ixx="0.00000" ixy="0" ixz="0" iyy="0.00000" iyz="0" izz="0.00000"/>
        </inertial>
    </link>
    <!-- TH0 joint -->
    <joint name="THJ0" type="revolute">
        <parent link="thmiddle"/>
        <child link="thdistal"/>
        <origin xyz="-0.0217524 -0.00531475 0.0143741"/>
        <axis xyz="1 0 0"/>
        <limit effort="1000.0" lower="-0.50000" upper="0.50000" velocity="0.5"/>
        <dynamics damping="1.0" friction="0.0001"/>
    </joint>
    <joint name="THJ0_y" type="revolute">
        <parent link="thmiddle"/>
        <child link="thdistal"/>
        <origin xyz="-0.0217524 -0.00531475 0.0143741"/>
        <axis xyz="0 1 0"/>
        <limit effort="1000.0" lower="-0.50000" upper="0.50000" velocity="0.5"/>
        <dynamics damping="1.0" friction="0.0001"/>
    </joint>
    <joint name="THJ0_z" type="revolute">
        <parent link="thmiddle"/>
        <child link="thdistal"/>
        <origin xyz="-0.0217524 -0.00531475 0.0143741"/>
        <axis xyz="0 0 1"/>
        <limit effort="1000.0" lower="-0.50000" upper="0.50000" velocity="0.5"/>
        <dynamics damping="1.0" friction="0.0001"/>
    </joint>


</robot>