<?xml version="1.0" ?>
<robot name="waffleiron">
   <material name="obj_color">
      <color rgba="1.0 0.423529411765 0.0392156862745 1.0"/>
   </material>
   <link name="top">
      <inertial>
         <origin rpy="0.0002415293256200118 0.0003741848138325245 0.0006047615474682893" xyz="0.1059238980011485 0.004174514503576319 0.04642083699990057"/>
         <mass value="0.1445078911604559"/>
         <inertia ixx="0.0002470635335913814" ixy="-4.333427877035367e-05" ixz="6.229921100834177e-06" iyy="0.0005995057353949245" iyz="-4.185044488387247e-07" izz="0.0003739064179345199"/>
      </inertial>
      <visual>
         <origin rpy="0 0 0" xyz="0 0 0"/>
         <geometry>
            <mesh filename="top_watertight_tiny.stl" scale="1 1 1"/>
         </geometry>
         <material name="obj_color"/>
      </visual>
      <collision>
         <origin rpy="0 0 0" xyz="0 0 0"/>
         <geometry>
            <mesh filename="top_watertight_tiny.obj" scale="1 1 1"/>
         </geometry>
      </collision>
   </link>
   <link name="bottom">
      <inertial>
         <origin rpy="0.001992789349100054 0.002529068396471172 0.004490094021441377" xyz="0.09624654269935466 0.02366628504861968 0.04590963024498602"/>
         <mass value="1.068060912552084"/>
         <inertia ixx="0.002047044585022042" ixy="-0.0003614911524404876" ixz="1.990915096733769e-05" iyy="0.004436604772894065" iyz="3.853203336872841e-06" izz="0.002528302409096502"/>
      </inertial>
      <visual>
         <origin rpy="0 0 0" xyz="0 0 0"/>
         <geometry>
            <mesh filename="bottom_watertight_tiny.stl" scale="1 1 1"/>
         </geometry>
         <material name="obj_color"/>
      </visual>
      <collision>
         <origin rpy="0 0 0" xyz="0 0 0"/>
         <geometry>
            <mesh filename="bottom_watertight_tiny.obj" scale="1 1 1"/>
         </geometry>
      </collision>
   </link>
   <link name="world"/>
   <joint name="world_to_base" type="fixed">
      <origin xyz="0 0 0"/>
      <axis xyz="0 0 0"/>
      <parent link="world"/>
      <child link="bottom"/>
   </joint>
   <joint name="rotation" type="revolute">
      <origin xyz="0 0 0"/>
      <axis xyz="0 0 -1"/>
      <parent link="bottom"/>
      <child link="top"/>
      <dynamics damping="0.0" friction="0.000"/>
      <limit effort="1000" velocity="200" lower="0" upper="3.141592653589793"/>
   </joint>
</robot>
