<?xml version="1.0" ?>
<robot name="ketchup">
   <material name="obj_color">
      <color rgba="1.0 0.423529411765 0.0392156862745 1.0"/>
   </material>
   <link name="top">
      <inertial>
         <origin rpy="1.053697166941137e-06 1.281090536385504e-06 2.220443757011781e-06" xyz="0.007487533823646627 0.02574966577909059 -0.006195972879581655"/>
         <mass value="0.005559019486435759"/>
         <inertia ixx="2.196255524387527e-06" ixy="1.629953608907079e-07" ixz="-1.085217972162108e-08" iyy="1.121817140969148e-06" iyz="8.915361731318121e-08" izz="1.237158794981748e-06"/>
      </inertial>
      <visual>
         <origin rpy="0 0 0" xyz="0 0 0"/>
         <geometry>
            <mesh filename="top_watertight_tiny.stl" scale="1 1 1"/>
         </geometry>
         <material name="obj_color"/>
      </visual>
      <collision>
         <origin rpy="0 0 0" xyz="0 0 0"/>
         <geometry>
            <mesh filename="top_watertight_tiny.obj" scale="1 1 1"/>
         </geometry>
      </collision>
   </link>
   <link name="bottom">
      <inertial>
         <origin rpy="0.0003111517367316898 0.001794153590493836 0.001932949715694781" xyz="-0.1065095731528556 0.0127064691544299 -0.007640686942466999"/>
         <mass value="0.5700573317889485"/>
         <inertia ixx="0.000327540205957619" ixy="-0.0001601662078634189" ixz="-2.138205748964534e-07" iyy="0.001879168755748112" iyz="-6.193442711972026e-05" izz="0.001831546081214574"/>
      </inertial>
      <visual>
         <origin rpy="0 0 0" xyz="0 0 0"/>
         <geometry>
            <mesh filename="bottom_watertight_tiny.stl" scale="1 1 1"/>
         </geometry>
         <material name="obj_color"/>
      </visual>
      <collision>
         <origin rpy="0 0 0" xyz="0 0 0"/>
         <geometry>
            <mesh filename="bottom_watertight_tiny.obj" scale="1 1 1"/>
         </geometry>
      </collision>
   </link>
   <link name="world"/>
   <joint name="world_to_base" type="fixed">
      <origin xyz="0 0 0"/>
      <axis xyz="0 0 0"/>
      <parent link="world"/>
      <child link="bottom"/>
   </joint>
   <joint name="rotation" type="revolute">
      <origin xyz="0 0 0"/>
      <axis xyz="0 0 -1"/>
      <parent link="bottom"/>
      <child link="top"/>
      <dynamics damping="0.05" friction="0.0001"/>
      <limit effort="1000" velocity="200" lower="0" upper="2.5"/>
   </joint>
</robot>
