<?xml version="1.0" ?>
<robot name="capsulemachine">
   <material name="obj_color">
      <color rgba="1.0 0.423529411765 0.0392156862745 1.0"/>
   </material>
   <link name="top">
      <inertial>
         <origin rpy="3.174165344629271e-06 5.6423722558869e-06 8.529685765760339e-06" xyz="0.01734931530349852 -0.02643217802972016 0.03100137126338341"/>
         <mass value="0.02100576219130245"/>
         <inertia ixx="7.740959629505551e-06" ixy="1.285248131218809e-06" ixz="-6.965637833841618e-08" iyy="6.429268383071114e-06" iyz="-6.672937155895467e-08" izz="3.175995353699843e-06"/>
      </inertial>
      <visual>
         <origin rpy="0 0 0" xyz="0 0 0"/>
         <geometry>
            <mesh filename="top_watertight_tiny.stl" scale="1 1 1"/>
         </geometry>
         <material name="obj_color"/>
      </visual>
      <collision>
         <origin rpy="0 0 0" xyz="0 0 0"/>
         <geometry>
            <mesh filename="top_watertight_tiny.obj" scale="1 1 1"/>
         </geometry>
      </collision>
   </link>
   <link name="bottom">
      <inertial>
         <origin rpy="0.00169385750923834 0.003967045683350672 0.004405174207893504" xyz="0.05136700289804626 0.07950908968081023 0.03230708184257082"/>
         <mass value="1.048362679505015"/>
         <inertia ixx="0.002888615483331892" ixy="-0.00113440803234408" ixz="4.390395226812951e-05" iyy="0.002773756085873763" iyz="4.527114231560062e-05" izz="0.004403705831276858"/>
      </inertial>
      <visual>
         <origin rpy="0 0 0" xyz="0 0 0"/>
         <geometry>
            <mesh filename="bottom_watertight_tiny.stl" scale="1 1 1"/>
         </geometry>
         <material name="obj_color"/>
      </visual>
      <collision>
         <origin rpy="0 0 0" xyz="0 0 0"/>
         <geometry>
            <mesh filename="bottom_watertight_tiny.obj" scale="1 1 1"/>
         </geometry>
      </collision>
   </link>
   <joint name="rotation" type="revolute">
      <origin xyz="0 0 0"/>
      <axis xyz="0 0 -1"/>
      <parent link="bottom"/>
      <child link="top"/>
      <dynamics damping="0.0" friction="0.000"/>
      <limit effort="1000" velocity="200" lower="0" upper="3.141592653589793"/>
   </joint>
</robot>
